<?xml version="1.0" ?>
<!-- =================================================================================== -->
<!-- |    This document was autogenerated by xacro from kmr_iiwa.urdf.xacro            | -->
<!-- |    EDITING THIS FILE BY HAND IS NOT RECOMMENDED                                 | -->
<!-- =================================================================================== -->
<robot name="kmr_iiwa">
  <!-- ==================================================================
       KMR (KUKA Mobile Robot) base
       - base_link origin is at floor level, centered in the footprint,
         X axis pointing towards the iiwa mounting side (as measured in
         SolidWorks / from the STEP file).
       - Wheels are fused into the base mesh (kinematic base motion only,
         no per-wheel joints/physics).
       ================================================================== -->
  <material name="Black">
    <color rgba="0.0 0.0 0.0 1.0"/>
  </material>
  <material name="Blue">
    <color rgba="0.0 0.0 0.8 1.0"/>
  </material>
  <material name="Green">
    <color rgba="0.0 0.8 0.0 1.0"/>
  </material>
  <material name="Grey">
    <color rgba="0.3 0.3 0.3 1.0"/>
  </material>
  <material name="Orange">
    <color rgba="1.0 0.4235294117647059 0.0392156862745098 1.0"/>
  </material>
  <material name="Brown">
    <color rgba="0.8705882352941177 0.8117647058823529 0.7647058823529411 1.0"/>
  </material>
  <material name="Red">
    <color rgba="0.8 0.0 0.0 1.0"/>
  </material>
  <material name="White">
    <color rgba="1.0 1.0 1.0 1.0"/>
  </material>
  <!-- m, Z direction -->
  <!-- base_link -->
  <link name="base_link">
    <!-- grey main body -->
    <visual>
      <origin rpy="0 0 0" xyz="-0.54 -0.315 0"/>
      <geometry>
        <mesh filename="../meshes/kmr_base/kmr_base_body.stl" scale="1 1 1"/>
      </geometry>
      <material name="Grey">
        <color rgba="0.3 0.3 0.3 1.0"/>
      </material>
    </visual>
    <!-- orange bottom skirt -->
    <visual>
      <origin rpy="0 0 0" xyz="-0.54 -0.315 0"/>
      <geometry>
        <mesh filename="../meshes/kmr_base/kmr_base_skirt.stl" scale="1 1 1"/>
      </geometry>
      <material name="Orange">
        <color rgba="1.0 0.4235294117647059 0.0392156862745098 1.0"/>
      </material>
    </visual>
    <collision>
      <origin rpy="0 0 0" xyz="0 0 0.35"/>
      <geometry>
        <box size="1.08 0.63 0.7"/>
      </geometry>
    </collision>
    <inertial>
      <origin rpy="0 0 0" xyz="0 0 0.35"/>
      <mass value="390.0"/>
      <!-- Solid-box inertia approximation -->
      <inertia ixx="28.82425" ixy="0.0" ixz="0.0" iyy="53.833000000000006" iyz="0.0" izz="50.80725"/>
    </inertial>
  </link>
  <!-- Optional: base_footprint at ground level, base_link elevated.
       Useful if you want a clean planar joint to "world"/"odom" for the
       kinematic Twist-driven motion in Isaac Sim. Uncomment if needed.

  <link name="base_footprint"/>

  <joint name="base_footprint_to_base_link" type="fixed">
    <parent link="base_footprint"/>
    <child link="base_link"/>
    <origin xyz="0 0 0" rpy="0 0 0"/>
  </joint>
  -->
  <!-- Primjer korištenja u kmr_iiwa lancu:
  <xacro:include filename="$(find kmr_iiwa_description)/xacro/gripper.xacro"/>
  <xacro:kmr_gripper parent="iiwa_link_ee">
    <origin xyz="0 0 0" rpy="0 0 0"/>
  </xacro:kmr_gripper>
  -->
  <!--joint between {parent} and link_0-->
  <joint name="base_link_iiwa_joint" type="fixed">
    <origin rpy="0 0 0" xyz="0.363 -0.184 0.7"/>
    <parent link="base_link"/>
    <child link="iiwa_link_0"/>
  </joint>
  <link name="iiwa_link_0">
    <inertial>
      <origin rpy="0 0 0" xyz="-0.1 0 0.07"/>
      <mass value="5"/>
      <inertia ixx="0.05" ixy="0" ixz="0" iyy="0.06" iyz="0" izz="0.03"/>
    </inertial>
    <visual>
      <origin rpy="0 0 0" xyz="0 0 0"/>
      <geometry>
        <mesh filename="../meshes/iiwa7/visual/link_0.stl"/>
      </geometry>
      <material name="Grey"/>
    </visual>
    <collision>
      <origin rpy="0 0 0" xyz="0 0 0"/>
      <geometry>
        <mesh filename="../meshes/iiwa7/collision/link_0.stl"/>
      </geometry>
      <material name="Grey"/>
    </collision>
    <self_collision_checking>
      <origin rpy="0 0 0" xyz="0 0 0"/>
      <geometry>
        <capsule length="0.25" radius="0.15"/>
      </geometry>
    </self_collision_checking>
  </link>
  <!-- joint between link_0 and link_1 -->
  <joint name="iiwa_joint_1" type="revolute">
    <parent link="iiwa_link_0"/>
    <child link="iiwa_link_1"/>
    <origin rpy="0 0 0" xyz="0 0 0.15"/>
    <axis xyz="0 0 1"/>
    <limit effort="300" lower="-2.9670597283903604" upper="2.9670597283903604" velocity="10"/>
    <safety_controller k_position="100" k_velocity="2" soft_lower_limit="-2.9321531433504737" soft_upper_limit="2.9321531433504737"/>
    <dynamics damping="0.5"/>
  </joint>
  <link name="iiwa_link_1">
    <inertial>
      <origin rpy="0 0 0" xyz="0 -0.03 0.12"/>
      <mass value="3.4525"/>
      <inertia ixx="0.02183" ixy="0" ixz="0" iyy="0.007703" iyz="-0.003887" izz="0.02083"/>
    </inertial>
    <visual>
      <origin rpy="0 0 0" xyz="0 0 0.0075"/>
      <geometry>
        <mesh filename="../meshes/iiwa7/visual/link_1.stl"/>
      </geometry>
      <material name="Orange"/>
    </visual>
    <collision>
      <origin rpy="0 0 0" xyz="0 0 0.0075"/>
      <geometry>
        <mesh filename="../meshes/iiwa7/collision/link_1.stl"/>
      </geometry>
      <material name="Orange"/>
    </collision>
  </link>
  <joint name="iiwa_joint_2" type="revolute">
    <parent link="iiwa_link_1"/>
    <child link="iiwa_link_2"/>
    <origin rpy="1.5707963267948966   0 3.141592653589793" xyz="0 0 0.19"/>
    <axis xyz="0 0 1"/>
    <limit effort="300" lower="-2.0943951023931953" upper="2.0943951023931953" velocity="10"/>
    <safety_controller k_position="100" k_velocity="2" soft_lower_limit="-2.0594885173533086" soft_upper_limit="2.0594885173533086"/>
    <dynamics damping="0.5"/>
  </joint>
  <link name="iiwa_link_2">
    <inertial>
      <origin rpy="0 0 0" xyz="0.0003 0.059 0.042"/>
      <mass value="3.4821"/>
      <inertia ixx="0.02076" ixy="0" ixz="-0.003626" iyy="0.02179" iyz="0" izz="0.00779"/>
    </inertial>
    <visual>
      <origin rpy="0 0 0" xyz="0 0 0"/>
      <geometry>
        <mesh filename="../meshes/iiwa7/visual/link_2.stl"/>
      </geometry>
      <material name="Orange"/>
    </visual>
    <collision>
      <origin rpy="0 0 0" xyz="0 0 0"/>
      <geometry>
        <mesh filename="../meshes/iiwa7/collision/link_2.stl"/>
      </geometry>
      <material name="Orange"/>
    </collision>
  </link>
  <joint name="iiwa_joint_3" type="revolute">
    <parent link="iiwa_link_2"/>
    <child link="iiwa_link_3"/>
    <origin rpy="1.5707963267948966 0 3.141592653589793" xyz="0 0.21 0"/>
    <axis xyz="0 0 1"/>
    <limit effort="300" lower="-2.9670597283903604" upper="2.9670597283903604" velocity="10"/>
    <safety_controller k_position="100" k_velocity="2" soft_lower_limit="-2.9321531433504737" soft_upper_limit="2.9321531433504737"/>
    <dynamics damping="0.5"/>
  </joint>
  <link name="iiwa_link_3">
    <inertial>
      <origin rpy="0 0 0" xyz="0 0.03 0.13"/>
      <mass value="4.05623"/>
      <inertia ixx="0.03204" ixy="0" ixz="0" iyy="0.00972" iyz="0.006227" izz="0.03042"/>
    </inertial>
    <visual>
      <origin rpy="0 0 0" xyz="0 0 -0.026"/>
      <geometry>
        <mesh filename="../meshes/iiwa7/visual/link_3.stl"/>
      </geometry>
      <material name="Orange"/>
    </visual>
    <collision>
      <origin rpy="0 0 0" xyz="0 0 -0.026"/>
      <geometry>
        <mesh filename="../meshes/iiwa7/collision/link_3.stl"/>
      </geometry>
      <material name="Orange"/>
    </collision>
  </link>
  <joint name="iiwa_joint_4" type="revolute">
    <parent link="iiwa_link_3"/>
    <child link="iiwa_link_4"/>
    <origin rpy="1.5707963267948966 0 0" xyz="0 0 0.19"/>
    <axis xyz="0 0 1"/>
    <limit effort="300" lower="-2.0943951023931953" upper="2.0943951023931953" velocity="10"/>
    <safety_controller k_position="100" k_velocity="2" soft_lower_limit="-2.0594885173533086" soft_upper_limit="2.0594885173533086"/>
    <dynamics damping="0.5"/>
  </joint>
  <link name="iiwa_link_4">
    <inertial>
      <origin rpy="0 0 0" xyz="0 0.067 0.034"/>
      <mass value="3.4822"/>
      <inertia ixx="0.02178" ixy="0" ixz="0" iyy="0.02075" iyz="-0.003625" izz="0.007785"/>
    </inertial>
    <visual>
      <origin rpy="0 0 0" xyz="0 0 0"/>
      <geometry>
        <mesh filename="../meshes/iiwa7/visual/link_4.stl"/>
      </geometry>
      <material name="Orange"/>
    </visual>
    <collision>
      <origin rpy="0 0 0" xyz="0 0 0"/>
      <geometry>
        <mesh filename="../meshes/iiwa7/collision/link_4.stl"/>
      </geometry>
      <material name="Orange"/>
    </collision>
  </link>
  <joint name="iiwa_joint_5" type="revolute">
    <parent link="iiwa_link_4"/>
    <child link="iiwa_link_5"/>
    <origin rpy="-1.5707963267948966 3.141592653589793 0" xyz="0 0.21 0"/>
    <axis xyz="0 0 1"/>
    <limit effort="300" lower="-2.9670597283903604" upper="2.9670597283903604" velocity="10"/>
    <safety_controller k_position="100" k_velocity="2" soft_lower_limit="-2.9321531433504737" soft_upper_limit="2.9321531433504737"/>
    <dynamics damping="0.5"/>
  </joint>
  <link name="iiwa_link_5">
    <inertial>
      <origin rpy="0 0 0" xyz="0.0001 0.021 0.076"/>
      <mass value="2.1633"/>
      <inertia ixx="0.01287" ixy="0" ixz="0" iyy="0.005708" iyz="-0.003946" izz="0.01112"/>
    </inertial>
    <visual>
      <origin rpy="0 0 0" xyz="0 0 -0.026"/>
      <geometry>
        <mesh filename="../meshes/iiwa7/visual/link_5.stl"/>
      </geometry>
      <material name="Orange"/>
    </visual>
    <collision>
      <origin rpy="0 0 0" xyz="0 0 -0.026"/>
      <geometry>
        <mesh filename="../meshes/iiwa7/collision/link_5.stl"/>
      </geometry>
      <material name="Orange"/>
    </collision>
  </link>
  <joint name="iiwa_joint_6" type="revolute">
    <parent link="iiwa_link_5"/>
    <child link="iiwa_link_6"/>
    <origin rpy="1.5707963267948966 0 0" xyz="0 0.06070 0.19"/>
    <axis xyz="0 0 1"/>
    <limit effort="300" lower="-2.0943951023931953" upper="2.0943951023931953" velocity="10"/>
    <safety_controller k_position="100" k_velocity="2" soft_lower_limit="-2.0594885173533086" soft_upper_limit="2.0594885173533086"/>
    <dynamics damping="0.5"/>
  </joint>
  <link name="iiwa_link_6">
    <inertial>
      <origin rpy="0 0 0" xyz="0 0.0006 0.0004"/>
      <mass value="2.3466"/>
      <inertia ixx="0.006509" ixy="0" ixz="0" iyy="0.006259" iyz="0.00031891" izz="0.004527"/>
    </inertial>
    <visual>
      <origin rpy="0 0 0" xyz="0 0 0"/>
      <geometry>
        <mesh filename="../meshes/iiwa7/visual/link_6.stl"/>
      </geometry>
      <material name="Orange"/>
    </visual>
    <collision>
      <origin rpy="0 0 0" xyz="0 0 0"/>
      <geometry>
        <mesh filename="../meshes/iiwa7/collision/link_6.stl"/>
      </geometry>
      <material name="Orange"/>
    </collision>
  </link>
  <joint name="iiwa_joint_7" type="revolute">
    <parent link="iiwa_link_6"/>
    <child link="iiwa_link_7"/>
    <origin rpy="-1.5707963267948966 3.141592653589793 0" xyz="0 0.081 0.06070"/>
    <axis xyz="0 0 1"/>
    <limit effort="300" lower="-3.0543261909900763" upper="3.0543261909900763" velocity="10"/>
    <safety_controller k_position="100" k_velocity="2" soft_lower_limit="-3.01941960595019" soft_upper_limit="3.01941960595019"/>
    <dynamics damping="0.5"/>
  </joint>
  <link name="iiwa_link_7">
    <inertial>
      <origin rpy="0 0 0" xyz="0 0 0.02"/>
      <mass value="3.129"/>
      <inertia ixx="0.01464" ixy="0.0005912" ixz="0" iyy="0.01465" iyz="0" izz="0.002872"/>
    </inertial>
    <visual>
      <origin rpy="0 0 0" xyz="0 0 -0.0005"/>
      <geometry>
        <mesh filename="../meshes/iiwa7/visual/link_7.stl"/>
      </geometry>
      <material name="Grey"/>
    </visual>
    <collision>
      <origin rpy="0 0 0" xyz="0 0 -0.0005"/>
      <geometry>
        <mesh filename="../meshes/iiwa7/collision/link_7.stl"/>
      </geometry>
      <material name="Grey"/>
    </collision>
  </link>
  <joint name="iiwa_joint_ee" type="fixed">
    <parent link="iiwa_link_7"/>
    <child link="iiwa_link_ee"/>
    <origin rpy="0 0 0" xyz="0 0 0.045"/>
  </joint>
  <link name="iiwa_link_ee">
    </link>
  <!-- Load Gazebo lib and set the robot namespace -->
  <!-- <gazebo>
      <plugin name="gazebo_ros_control" filename="libgazebo_ros_control.so">
        <robotNamespace>/${robot_name}</robotNamespace>
      </plugin>
    </gazebo> -->
  <!-- Link0 -->
  <gazebo reference="iiwa_link_0">
    <material>Gazebo/Grey</material>
    <mu1>0.2</mu1>
    <mu2>0.2</mu2>
  </gazebo>
  <!-- Link1 -->
  <gazebo reference="iiwa_link_1">
    <material>Gazebo/Orange</material>
    <mu1>0.2</mu1>
    <mu2>0.2</mu2>
  </gazebo>
  <!-- Link2 -->
  <gazebo reference="iiwa_link_2">
    <material>Gazebo/Orange</material>
    <mu1>0.2</mu1>
    <mu2>0.2</mu2>
  </gazebo>
  <!-- Link3 -->
  <gazebo reference="iiwa_link_3">
    <material>Gazebo/Orange</material>
    <mu1>0.2</mu1>
    <mu2>0.2</mu2>
  </gazebo>
  <!-- Link4 -->
  <gazebo reference="iiwa_link_4">
    <material>Gazebo/Orange</material>
    <mu1>0.2</mu1>
    <mu2>0.2</mu2>
  </gazebo>
  <!-- Link5 -->
  <gazebo reference="iiwa_link_5">
    <material>Gazebo/Orange</material>
    <mu1>0.2</mu1>
    <mu2>0.2</mu2>
  </gazebo>
  <!-- Link6 -->
  <gazebo reference="iiwa_link_6">
    <material>Gazebo/Orange</material>
    <mu1>0.2</mu1>
    <mu2>0.2</mu2>
  </gazebo>
  <!-- Link7 -->
  <gazebo reference="iiwa_link_7">
    <material>Gazebo/Grey</material>
    <mu1>0.2</mu1>
    <mu2>0.2</mu2>
  </gazebo>
  <transmission name="iiwa_tran_1">
    <robotNamespace>/iiwa</robotNamespace>
    <type>transmission_interface/SimpleTransmission</type>
    <joint name="iiwa_joint_1">
      <hardwareInterface>PositionJointInterface</hardwareInterface>
    </joint>
    <actuator name="iiwa_motor_1">
      <hardwareInterface>PositionJointInterface</hardwareInterface>
      <mechanicalReduction>1</mechanicalReduction>
    </actuator>
  </transmission>
  <transmission name="iiwa_tran_2">
    <robotNamespace>/iiwa</robotNamespace>
    <type>transmission_interface/SimpleTransmission</type>
    <joint name="iiwa_joint_2">
      <hardwareInterface>PositionJointInterface</hardwareInterface>
    </joint>
    <actuator name="iiwa_motor_2">
      <hardwareInterface>PositionJointInterface</hardwareInterface>
      <mechanicalReduction>1</mechanicalReduction>
    </actuator>
  </transmission>
  <transmission name="iiwa_tran_3">
    <robotNamespace>/iiwa</robotNamespace>
    <type>transmission_interface/SimpleTransmission</type>
    <joint name="iiwa_joint_3">
      <hardwareInterface>PositionJointInterface</hardwareInterface>
    </joint>
    <actuator name="iiwa_motor_3">
      <hardwareInterface>PositionJointInterface</hardwareInterface>
      <mechanicalReduction>1</mechanicalReduction>
    </actuator>
  </transmission>
  <transmission name="iiwa_tran_4">
    <robotNamespace>/iiwa</robotNamespace>
    <type>transmission_interface/SimpleTransmission</type>
    <joint name="iiwa_joint_4">
      <hardwareInterface>PositionJointInterface</hardwareInterface>
    </joint>
    <actuator name="iiwa_motor_4">
      <hardwareInterface>PositionJointInterface</hardwareInterface>
      <mechanicalReduction>1</mechanicalReduction>
    </actuator>
  </transmission>
  <transmission name="iiwa_tran_5">
    <robotNamespace>/iiwa</robotNamespace>
    <type>transmission_interface/SimpleTransmission</type>
    <joint name="iiwa_joint_5">
      <hardwareInterface>PositionJointInterface</hardwareInterface>
    </joint>
    <actuator name="iiwa_motor_5">
      <hardwareInterface>PositionJointInterface</hardwareInterface>
      <mechanicalReduction>1</mechanicalReduction>
    </actuator>
  </transmission>
  <transmission name="iiwa_tran_6">
    <robotNamespace>/iiwa</robotNamespace>
    <type>transmission_interface/SimpleTransmission</type>
    <joint name="iiwa_joint_6">
      <hardwareInterface>PositionJointInterface</hardwareInterface>
    </joint>
    <actuator name="iiwa_motor_6">
      <hardwareInterface>PositionJointInterface</hardwareInterface>
      <mechanicalReduction>1</mechanicalReduction>
    </actuator>
  </transmission>
  <transmission name="iiwa_tran_7">
    <robotNamespace>/iiwa</robotNamespace>
    <type>transmission_interface/SimpleTransmission</type>
    <joint name="iiwa_joint_7">
      <hardwareInterface>PositionJointInterface</hardwareInterface>
    </joint>
    <actuator name="iiwa_motor_7">
      <hardwareInterface>PositionJointInterface</hardwareInterface>
      <mechanicalReduction>1</mechanicalReduction>
    </actuator>
  </transmission>
  <material name="gripper_grey">
    <color rgba="0.35 0.35 0.38 1.0"/>
  </material>
  <material name="gripper_orange">
    <color rgba="0.85 0.35 0.05 1.0"/>
  </material>
  <!-- ================= BAZA ================= -->
  <link name="gripper_base">
    <inertial>
      <origin rpy="0 0 0" xyz="0 0 0.019417"/>
      <mass value="0.4416"/>
      <inertia ixx="2.4758e-04" ixy="0.0" ixz="0.0" iyy="2.5395e-04" iyz="0.0" izz="4.2682e-04"/>
    </inertial>
    <visual>
      <origin rpy="0 0 0" xyz="0 0 0"/>
      <geometry>
        <mesh filename="../meshes/gripper/gripper_base.stl"/>
      </geometry>
      <material name="gripper_grey"/>
    </visual>
    <!-- collision primitivima: disk (0..15mm, pokriva i skošenje) + ploča (15..35mm) -->
    <collision>
      <origin rpy="0 0 0" xyz="0 0 0.0075"/>
      <geometry>
        <cylinder length="0.015" radius="0.0315"/>
      </geometry>
    </collision>
    <collision>
      <origin rpy="0 0 0" xyz="0 0 0.025"/>
      <geometry>
        <box size="0.085 0.085 0.020"/>
      </geometry>
    </collision>
  </link>
  <!-- zglob na kojem se čita sila/moment -->
  <joint name="gripper_wrist_joint" type="fixed">
    <origin rpy="0 0 0" xyz="0 0 0"/>
    <parent link="iiwa_link_ee"/>
    <child link="gripper_base"/>
  </joint>
  <link name="gripper_finger_1">
    <inertial>
      <origin rpy="0 0 0" xyz="0.000568 0.027399 0.0075"/>
      <mass value="0.0306"/>
      <inertia ixx="1.0324e-05" ixy="-2.631e-07" ixz="0.0" iyy="1.1200e-06" iyz="0.0" izz="1.0298e-05"/>
    </inertial>
    <visual>
      <origin rpy="0 0 0" xyz="0 0 0"/>
      <geometry>
        <mesh filename="../meshes/gripper/gripper_finger.stl"/>
      </geometry>
      <material name="gripper_orange"/>
    </visual>
    <!-- mesh collision: OBAVEZNO convexDecomposition pri importu (konkavna kuka) -->
    <collision>
      <origin rpy="0 0 0" xyz="0 0 0"/>
      <geometry>
        <mesh filename="../meshes/gripper/gripper_finger.stl"/>
      </geometry>
    </collision>
  </link>
  <joint name="gripper_finger_1_joint" type="prismatic">
    <origin rpy="1.5707963267948966 0 0" xyz="0.035 0.0325 0.025"/>
    <parent link="gripper_base"/>
    <child link="gripper_finger_1"/>
    <!-- os u lokalnom okviru prsta; +q = zatvaranje prema centru za sva 4 prsta -->
    <axis xyz="-1 0 0"/>
    <limit effort="30.0" lower="0.0" upper="0.025" velocity="0.1"/>
    <!-- damping se ionako pregazi actuator konfiguracijom u Isaac Labu -->
    <dynamics damping="10.0" friction="0.0"/>
  </joint>
  <link name="gripper_finger_2">
    <inertial>
      <origin rpy="0 0 0" xyz="0.000568 0.027399 0.0075"/>
      <mass value="0.0306"/>
      <inertia ixx="1.0324e-05" ixy="-2.631e-07" ixz="0.0" iyy="1.1200e-06" iyz="0.0" izz="1.0298e-05"/>
    </inertial>
    <visual>
      <origin rpy="0 0 0" xyz="0 0 0"/>
      <geometry>
        <mesh filename="../meshes/gripper/gripper_finger.stl"/>
      </geometry>
      <material name="gripper_orange"/>
    </visual>
    <!-- mesh collision: OBAVEZNO convexDecomposition pri importu (konkavna kuka) -->
    <collision>
      <origin rpy="0 0 0" xyz="0 0 0"/>
      <geometry>
        <mesh filename="../meshes/gripper/gripper_finger.stl"/>
      </geometry>
    </collision>
  </link>
  <joint name="gripper_finger_2_joint" type="prismatic">
    <origin rpy="1.5707963267948966 0 0" xyz="0.035 -0.0175 0.025"/>
    <parent link="gripper_base"/>
    <child link="gripper_finger_2"/>
    <!-- os u lokalnom okviru prsta; +q = zatvaranje prema centru za sva 4 prsta -->
    <axis xyz="-1 0 0"/>
    <limit effort="30.0" lower="0.0" upper="0.025" velocity="0.1"/>
    <!-- damping se ionako pregazi actuator konfiguracijom u Isaac Labu -->
    <dynamics damping="10.0" friction="0.0"/>
  </joint>
  <link name="gripper_finger_3">
    <inertial>
      <origin rpy="0 0 0" xyz="0.000568 0.027399 0.0075"/>
      <mass value="0.0306"/>
      <inertia ixx="1.0324e-05" ixy="-2.631e-07" ixz="0.0" iyy="1.1200e-06" iyz="0.0" izz="1.0298e-05"/>
    </inertial>
    <visual>
      <origin rpy="0 0 0" xyz="0 0 0"/>
      <geometry>
        <mesh filename="../meshes/gripper/gripper_finger.stl"/>
      </geometry>
      <material name="gripper_orange"/>
    </visual>
    <!-- mesh collision: OBAVEZNO convexDecomposition pri importu (konkavna kuka) -->
    <collision>
      <origin rpy="0 0 0" xyz="0 0 0"/>
      <geometry>
        <mesh filename="../meshes/gripper/gripper_finger.stl"/>
      </geometry>
    </collision>
  </link>
  <joint name="gripper_finger_3_joint" type="prismatic">
    <origin rpy="1.5707963267948966 0 3.141592653589793" xyz="-0.035 0.0175 0.025"/>
    <parent link="gripper_base"/>
    <child link="gripper_finger_3"/>
    <!-- os u lokalnom okviru prsta; +q = zatvaranje prema centru za sva 4 prsta -->
    <axis xyz="-1 0 0"/>
    <limit effort="30.0" lower="0.0" upper="0.025" velocity="0.1"/>
    <!-- damping se ionako pregazi actuator konfiguracijom u Isaac Labu -->
    <dynamics damping="10.0" friction="0.0"/>
  </joint>
  <link name="gripper_finger_4">
    <inertial>
      <origin rpy="0 0 0" xyz="0.000568 0.027399 0.0075"/>
      <mass value="0.0306"/>
      <inertia ixx="1.0324e-05" ixy="-2.631e-07" ixz="0.0" iyy="1.1200e-06" iyz="0.0" izz="1.0298e-05"/>
    </inertial>
    <visual>
      <origin rpy="0 0 0" xyz="0 0 0"/>
      <geometry>
        <mesh filename="../meshes/gripper/gripper_finger.stl"/>
      </geometry>
      <material name="gripper_orange"/>
    </visual>
    <!-- mesh collision: OBAVEZNO convexDecomposition pri importu (konkavna kuka) -->
    <collision>
      <origin rpy="0 0 0" xyz="0 0 0"/>
      <geometry>
        <mesh filename="../meshes/gripper/gripper_finger.stl"/>
      </geometry>
    </collision>
  </link>
  <joint name="gripper_finger_4_joint" type="prismatic">
    <origin rpy="1.5707963267948966 0 3.141592653589793" xyz="-0.035 -0.0325 0.025"/>
    <parent link="gripper_base"/>
    <child link="gripper_finger_4"/>
    <!-- os u lokalnom okviru prsta; +q = zatvaranje prema centru za sva 4 prsta -->
    <axis xyz="-1 0 0"/>
    <limit effort="30.0" lower="0.0" upper="0.025" velocity="0.1"/>
    <!-- damping se ionako pregazi actuator konfiguracijom u Isaac Labu -->
    <dynamics damping="10.0" friction="0.0"/>
  </joint>
  <!-- ================= TCP ================= -->
  <!-- referentna točka: os šipke u hvatu (centar unutarnjeg luka kuka pri q=0.025) -->
  <link name="gripper_tcp"/>
  <joint name="gripper_tcp_joint" type="fixed">
    <origin rpy="0 0 0" xyz="0 0 0.07485"/>
    <parent link="gripper_base"/>
    <child link="gripper_tcp"/>
  </joint>
</robot>
